Workbook

Sheet Hesaplama Aracı
B2: Vana Seçim Aracı
B3: Adet | C3: Çap | D3: Vana Tipi | E3: Basınç Sınıfı(PN)
B4: 1 | C4: DN300 | D4: Sürgülü Vana | E4: PN10 | T4: Çap | U4: Kalınlık
L5: 1 | M5: DN40 | N5: Demontaj | O5: PN6 | R5: 4 | T5: DN15 | U5: 1.5 | W5: 21.3
B6: Conta Sayısı | C6: Delik Sayısı | D6: Vana Uzunluğu | L6: 2 | M6: DN50 | N6: Sürgülü Vana | O6: PN10 | R6: 6 | T6: DN15 | U6: 1.6 | W6: 25.4
B7: =B4*2 -> 2 | C7: {=INDEX(Vanalar!$A$1:$H$178,MATCH(1,(C4=Vanalar!$A:$A)*(D4=Vanalar!$B:$B)*(E4=Vanalar!$C:$C),0),6)} -> 12 | D7: {=INDEX(Vanalar!$A$1:$H$178,MATCH(1,($C$4=Vanalar!$A:$A)*($D$4=Vanalar!$B:$B)*($E$4=Vanalar!$C:$C),0),7)} -> 270 | L7: 3 | M7: DN65 | N7: Bıçaklı Vana | O7: PN16 | R7: 8 | T7: DN20 | U7: 2 | W7: 33.7
L8: 4 | M8: DN80 | N8: Wafer Kelebek Vana | R8: 10 | T8: DN25 | U8: 2.5 | W8: 42.4
B9: Civata Ölçüsü | C9: Civata Sayısı | D9: Somun Sayısı | E9: Pul Sayısı | L9: 5 | M9: DN100 | N9: Ağırlık Kollu Çekvalf | R9: 12 | T9: DN32 | U9: 2.6 | W9: 48.3
B10: {=INDEX(Vanalar!A1:H178,MATCH(1,(C4=Vanalar!A:A)*(D4=Vanalar!B:B)*(E4=Vanalar!C:C),0),8)} -> M20x120mm | C10: =IF(D4=N5,"0",C7*2*B4) -> 24 | D10: =IF(OR(D4=N7,D4=N11,D4=N5),C7*0,C7*2)*B4 -> 24 | E10: =IF(OR(D4=N7,D4=N11,D4=N5),C7*2,C7*2)*B4 -> 24 | L10: 6 | M10: DN125 | N10: Çalpara Çekvalf | R10: 14 | T10: DN40 | U10: 1.8 | W10: 60.3
L11: 7 | M11: DN150 | N11: Lug Kelebek Vana | R11: 16 | T11: DN50 | U11: 3 | W11: 76.1
L12: 8 | M12: DN200 | R12: 18 | T12: DN65 | U12: 2.7 | W12: 88.9
L13: 14 | M13: DN500 | R13: 33 | T13: DN250 | U13: 7.92 | W13: 323.9
L14: 15 | M14: DN600 | R14: 36 | T14: DN300 | U14: 9.52 | W14: 355.6
L15: 25
L16: 26
L17: 50

Sheet Paslanmaz Boru
A2: Çap | B2: Cins | C2: Dış Çap(ømm) | D2: Et Kalınlığı(mm) | E2: Ağırlık(kg/mt) | F2: Elektrot 2,5mm2 | G2: Elektrot 3,25mm2
A3: DN15 | B3: Boru | C3: 21.3 | D3: 1.5 | E3: 0.744 | F3: =_xlfn.CEILING.MATH(2*Tablo1[[#This Row],[Dış Çap(ømm)]]*3.14*Tablo1[[#This Row],[Et Kalınlığı(mm)]]*3/1000*7.85*1.4/20,1) -> 1 | G3: =_xlfn.CEILING.MATH(2*Tablo1[[#This Row],[Dış Çap(ømm)]]*3.14*Tablo1[[#This Row],[Et Kalınlığı(mm)]]*3/1000*7.85*1.4/35,1) -> 1
A4: DN15 | B4: Boru | C4: 21.3 | D4: 1.6 | E4: 0.789 | F4: =_xlfn.CEILING.MATH(2*Tablo1[[#This Row],[Dış Çap(ømm)]]*3.14*Tablo1[[#This Row],[Et Kalınlığı(mm)]]*3/1000*7.85*1.4/20,1) -> 1 | G4: =_xlfn.CEILING.MATH(2*Tablo1[[#This Row],[Dış Çap(ømm)]]*3.14*Tablo1[[#This Row],[Et Kalınlığı(mm)]]*3/1000*7.85*1.4/35,1) -> 1
A5: DN15 | B5: Boru | C5: 21.3 | D5: 2 | E5: 0.967 | F5: =_xlfn.CEILING.MATH(2*Tablo1[[#This Row],[Dış Çap(ømm)]]*3.14*Tablo1[[#This Row],[Et Kalınlığı(mm)]]*3/1000*7.85*1.4/20,1) -> 1 | G5: =_xlfn.CEILING.MATH(2*Tablo1[[#This Row],[Dış Çap(ømm)]]*3.14*Tablo1[[#This Row],[Et Kalınlığı(mm)]]*3/1000*7.85*1.4/35,1) -> 1
A6: DN15 | B6: Boru | C6: 21.3 | D6: 2.5 | E6: 1.177 | F6: =_xlfn.CEILING.MATH(2*Tablo1[[#This Row],[Dış Çap(ømm)]]*3.14*Tablo1[[#This Row],[Et Kalınlığı(mm)]]*3/1000*7.85*1.4/20,1) -> 1 | G6: =_xlfn.CEILING.MATH(2*Tablo1[[#This Row],[Dış Çap(ømm)]]*3.14*Tablo1[[#This Row],[Et Kalınlığı(mm)]]*3/1000*7.85*1.4/35,1) -> 1
A7: DN15 | B7: Boru | C7: 21.3 | D7: 2.5 | E7: 1.217 | F7: =_xlfn.CEILING.MATH(2*Tablo1[[#This Row],[Dış Çap(ømm)]]*3.14*Tablo1[[#This Row],[Et Kalınlığı(mm)]]*3/1000*7.85*1.4/20,1) -> 1 | G7: =_xlfn.CEILING.MATH(2*Tablo1[[#This Row],[Dış Çap(ømm)]]*3.14*Tablo1[[#This Row],[Et Kalınlığı(mm)]]*3/1000*7.85*1.4/35,1) -> 1
A8: DN15 | B8: Boru | C8: 21.3 | D8: 2.6 | E8: 1.375 | F8: =_xlfn.CEILING.MATH(2*Tablo1[[#This Row],[Dış Çap(ømm)]]*3.14*Tablo1[[#This Row],[Et Kalınlığı(mm)]]*3/1000*7.85*1.4/20,1) -> 1 | G8: =_xlfn.CEILING.MATH(2*Tablo1[[#This Row],[Dış Çap(ømm)]]*3.14*Tablo1[[#This Row],[Et Kalınlığı(mm)]]*3/1000*7.85*1.4/35,1) -> 1
A9: DN20 | B9: Boru | C9: 25.4 | D9: 1.5 | E9: 0.898 | F9: =_xlfn.CEILING.MATH(2*Tablo1[[#This Row],[Dış Çap(ømm)]]*3.14*Tablo1[[#This Row],[Et Kalınlığı(mm)]]*3/1000*7.85*1.4/20,1) -> 1 | G9: =_xlfn.CEILING.MATH(2*Tablo1[[#This Row],[Dış Çap(ømm)]]*3.14*Tablo1[[#This Row],[Et Kalınlığı(mm)]]*3/1000*7.85*1.4/35,1) -> 1
A10: DN20 | B10: Boru | C10: 25.4 | D10: 1.6 | E10: 0.981 | F10: =_xlfn.CEILING.MATH(2*Tablo1[[#This Row],[Dış Çap(ømm)]]*3.14*Tablo1[[#This Row],[Et Kalınlığı(mm)]]*3/1000*7.85*1.4/20,1) -> 1 | G10: =_xlfn.CEILING.MATH(2*Tablo1[[#This Row],[Dış Çap(ømm)]]*3.14*Tablo1[[#This Row],[Et Kalınlığı(mm)]]*3/1000*7.85*1.4/35,1) -> 1
A11: DN20 | B11: Boru | C11: 25.4 | D11: 1.8 | E11: 0.995 | F11: =_xlfn.CEILING.MATH(2*Tablo1[[#This Row],[Dış Çap(ømm)]]*3.14*Tablo1[[#This Row],[Et Kalınlığı(mm)]]*3/1000*7.85*1.4/20,1) -> 1 | G11: =_xlfn.CEILING.MATH(2*Tablo1[[#This Row],[Dış Çap(ømm)]]*3.14*Tablo1[[#This Row],[Et Kalınlığı(mm)]]*3/1000*7.85*1.4/35,1) -> 1
A12: DN20 | B12: Boru | C12: 25.4 | D12: 2 | E12: 1.172 | F12: =_xlfn.CEILING.MATH(2*Tablo1[[#This Row],[Dış Çap(ømm)]]*3.14*Tablo1[[#This Row],[Et Kalınlığı(mm)]]*3/1000*7.85*1.4/20,1) -> 1 | G12: =_xlfn.CEILING.MATH(2*Tablo1[[#This Row],[Dış Çap(ømm)]]*3.14*Tablo1[[#This Row],[Et Kalınlığı(mm)]]*3/1000*7.85*1.4/35,1) -> 1
A13: DN20 | B13: Boru | C13: 25.4 | D13: 3 | E13: 1.683 | F13: =_xlfn.CEILING.MATH(2*Tablo1[[#This Row],[Dış Çap(ømm)]]*3.14*Tablo1[[#This Row],[Et Kalınlığı(mm)]]*3/1000*7.85*1.4/20,1) -> 1 | G13: =_xlfn.CEILING.MATH(2*Tablo1[[#This Row],[Dış Çap(ømm)]]*3.14*Tablo1[[#This Row],[Et Kalınlığı(mm)]]*3/1000*7.85*1.4/35,1) -> 1
A14: DN25 | B14: Boru | C14: 33.7 | D14: 1.5 | E14: 1.209 | F14: =_xlfn.CEILING.MATH(2*Tablo1[[#This Row],[Dış Çap(ømm)]]*3.14*Tablo1[[#This Row],[Et Kalınlığı(mm)]]*3/1000*7.85*1.4/20,1) -> 1 | G14: =_xlfn.CEILING.MATH(2*Tablo1[[#This Row],[Dış Çap(ømm)]]*3.14*Tablo1[[#This Row],[Et Kalınlığı(mm)]]*3/1000*7.85*1.4/35,1) -> 1
... A95: DN1000 | B95: Boru | C95: 1016 | D95: 12.7 | E95: 322.102 | F95: =_xlfn.CEILING.MATH(2*Tablo1[[#This Row],[Dış Çap(ømm)]]*3.14*Tablo1[[#This Row],[Et Kalınlığı(mm)]]*3/1000*7.85*1.4/20,1) -> 134 | G95: =_xlfn.CEILING.MATH(2*Tablo1[[#This Row],[Dış Çap(ømm)]]*3.14*Tablo1[[#This Row],[Et Kalınlığı(mm)]]*3/1000*7.85*1.4/35,1) -> 77
A96: DN15 | B96: 90 Dirsek | C96: 21.3 | D96: 1.5 | E96: =Tablo1[[#This Row],[Dış Çap(ømm)]]/$C$140/$D$140*Tablo1[[#This Row],[Et Kalınlığı(mm)]] -> 0.13976378 | F96: =_xlfn.CEILING.MATH(2*Tablo1[[#This Row],[Dış Çap(ømm)]]*3.14*Tablo1[[#This Row],[Et Kalınlığı(mm)]]*3/1000*7.85*1.4/20,1) -> 1 | G96: =_xlfn.CEILING.MATH(2*Tablo1[[#This Row],[Dış Çap(ømm)]]*3.14*Tablo1[[#This Row],[Et Kalınlığı(mm)]]*3/1000*7.85*1.4/35,1) -> 1
A97: DN15 | B97: 90 Dirsek | C97: 21.3 | D97: 1.6 | E97: =Tablo1[[#This Row],[Dış Çap(ømm)]]/$C$140/$D$140*Tablo1[[#This Row],[Et Kalınlığı(mm)]] -> 0.14908136 | F97: =_xlfn.CEILING.MATH(2*Tablo1[[#This Row],[Dış Çap(ømm)]]*3.14*Tablo1[[#This Row],[Et Kalınlığı(mm)]]*3/1000*7.85*1.4/20,1) -> 1 | G97: =_xlfn.CEILING.MATH(2*Tablo1[[#This Row],[Dış Çap(ømm)]]*3.14*Tablo1[[#This Row],[Et Kalınlığı(mm)]]*3/1000*7.85*1.4/35,1) -> 1
A98: DN15 | B98: 90 Dirsek | C98: 21.3 | D98: 2 | E98: =Tablo1[[#This Row],[Dış Çap(ømm)]]/$C$140/$D$140*Tablo1[[#This Row],[Et Kalınlığı(mm)]] -> 0.18635171 | F98: =_xlfn.CEILING.MATH(2*Tablo1[[#This Row],[Dış Çap(ømm)]]*3.14*Tablo1[[#This Row],[Et Kalınlığı(mm)]]*3/1000*7.85*1.4/20,1) -> 1 | G98: =_xlfn.CEILING.MATH(2*Tablo1[[#This Row],[Dış Çap(ømm)]]*3.14*Tablo1[[#This Row],[Et Kalınlığı(mm)]]*3/1000*7.85*1.4/35,1) -> 1
A99: DN15 | B99: 90 Dirsek | C99: 21.3 | D99: 2.5 | E99: =Tablo1[[#This Row],[Dış Çap(ømm)]]/$C$140/$D$140*Tablo1[[#This Row],[Et Kalınlığı(mm)]] -> 0.23293963 | F99: =_xlfn.CEILING.MATH(2*Tablo1[[#This Row],[Dış Çap(ømm)]]*3.14*Tablo1[[#This Row],[Et Kalınlığı(mm)]]*3/1000*7.85*1.4/20,1) -> 1 | G99: =_xlfn.CEILING.MATH(2*Tablo1[[#This Row],[Dış Çap(ømm)]]*3.14*Tablo1[[#This Row],[Et Kalınlığı(mm)]]*3/1000*7.85*1.4/35,1) -> 1
A100: DN15 | B100: 90 Dirsek | C100: 21.3 | D100: 2.5 | E100: =Tablo1[[#This Row],[Dış Çap(ømm)]]/$C$140/$D$140*Tablo1[[#This Row],[Et Kalınlığı(mm)]] -> 0.23293963 | F100: =_xlfn.CEILING.MATH(2*Tablo1[[#This Row],[Dış Çap(ømm)]]*3.14*Tablo1[[#This Row],[Et Kalınlığı(mm)]]*3/1000*7.85*1.4/20,1) -> 1 | G100: =_xlfn.CEILING.MATH(2*Tablo1[[#This Row],[Dış Çap(ømm)]]*3.14*Tablo1[[#This Row],[Et Kalınlığı(mm)]]*3/1000*7.85*1.4/35,1) -> 1
A101: DN15 | B101: 90 Dirsek | C101: 21.3 | D101: 2.6 | E101: =Tablo1[[#This Row],[Dış Çap(ømm)]]/$C$140/$D$140*Tablo1[[#This Row],[Et Kalınlığı(mm)]] -> 0.24225722 | F101: =_xlfn.CEILING.MATH(2*Tablo1[[#This Row],[Dış Çap(ømm)]]*3.14*Tablo1[[#This Row],[Et Kalınlığı(mm)]]*3/1000*7.85*1.4/20,1) -> 1 | G101: =_xlfn.CEILING.MATH(2*Tablo1[[#This Row],[Dış Çap(ømm)]]*3.14*Tablo1[[#This Row],[Et Kalınlığı(mm)]]*3/1000*7.85*1.4/35,1) -> 1
A102: DN20 | B102: 90 Dirsek | C102: 25.4 | D102: 1.5 | E102: =Tablo1[[#This Row],[Dış Çap(ømm)]]/$C$140/$D$140*Tablo1[[#This Row],[Et Kalınlığı(mm)]] -> 0.16666667 | F102: =_xlfn.CEILING.MATH(2*Tablo1[[#This Row],[Dış Çap(ømm)]]*3.14*Tablo1[[#This Row],[Et Kalınlığı(mm)]]*3/1000*7.85*1.4/20,1) -> 1 | G102: =_xlfn.CEILING.MATH(2*Tablo1[[#This Row],[Dış Çap(ømm)]]*3.14*Tablo1[[#This Row],[Et Kalınlığı(mm)]]*3/1000*7.85*1.4/35,1) -> 1
A103: DN20 | B103: 90 Dirsek | C103: 25.4 | D103: 1.6 | E103: =Tablo1[[#This Row],[Dış Çap(ømm)]]/$C$140/$D$140*Tablo1[[#This Row],[Et Kalınlığı(mm)]] -> 0.17777778 | F103: =_xlfn.CEILING.MATH(2*Tablo1[[#This Row],[Dış Çap(ømm)]]*3.14*Tablo1[[#This Row],[Et Kalınlığı(mm)]]*3/1000*7.85*1.4/20,1) -> 1 | G103: =_xlfn.CEILING.MATH(2*Tablo1[[#This Row],[Dış Çap(ømm)]]*3.14*Tablo1[[#This Row],[Et Kalınlığı(mm)]]*3/1000*7.85*1.4/35,1) -> 1
A104: DN20 | B104: 90 Dirsek | C104: 25.4 | D104: 1.8 | E104: =Tablo1[[#This Row],[Dış Çap(ømm)]]/$C$140/$D$140*Tablo1[[#This Row],[Et Kalınlığı(mm)]] -> 0.2 | F104: =_xlfn.CEILING.MATH(2*Tablo1[[#This Row],[Dış Çap(ømm)]]*3.14*Tablo1[[#This Row],[Et Kalınlığı(mm)]]*3/1000*7.85*1.4/20,1) -> 1 | G104: =_xlfn.CEILING.MATH(2*Tablo1[[#This Row],[Dış Çap(ømm)]]*3.14*Tablo1[[#This Row],[Et Kalınlığı(mm)]]*3/1000*7.85*1.4/35,1) -> 1
A105: DN20 | B105: 90 Dirsek | C105: 25.4 | D105: 2 | E105: =Tablo1[[#This Row],[Dış Çap(ømm)]]/$C$140/$D$140*Tablo1[[#This Row],[Et Kalınlığı(mm)]] -> 0.22222222 | F105: =_xlfn.CEILING.MATH(2*Tablo1[[#This Row],[Dış Çap(ømm)]]*3.14*Tablo1[[#This Row],[Et Kalınlığı(mm)]]*3/1000*7.85*1.4/20,1) -> 1 | G105: =_xlfn.CEILING.MATH(2*Tablo1[[#This Row],[Dış Çap(ømm)]]*3.14*Tablo1[[#This Row],[Et Kalınlığı(mm)]]*3/1000*7.85*1.4/35,1) -> 1
A106: DN20 | B106: 90 Dirsek | C106: 25.4 | D106: 3 | E106: =Tablo1[[#This Row],[Dış Çap(ømm)]]/$C$140/$D$140*Tablo1[[#This Row],[Et Kalınlığı(mm)]] -> 0.33333333 | F106: =_xlfn.CEILING.MATH(2*Tablo1[[#This Row],[Dış Çap(ømm)]]*3.14*Tablo1[[#This Row],[Et Kalınlığı(mm)]]*3/1000*7.85*1.4/20,1) -> 1 | G106: =_xlfn.CEILING.MATH(2*Tablo1[[#This Row],[Dış Çap(ømm)]]*3.14*Tablo1[[#This Row],[Et Kalınlığı(mm)]]*3/1000*7.85*1.4/35,1) -> 1
A107: DN25 | B107: 90 Dirsek | C107: 33.7 | D107: 1.5 | E107: =Tablo1[[#This Row],[Dış Çap(ømm)]]/$C$140/$D$140*Tablo1[[#This Row],[Et Kalınlığı(mm)]] -> 0.22112861 | F107: =_xlfn.CEILING.MATH(2*Tablo1[[#This Row],[Dış Çap(ømm)]]*3.14*Tablo1[[#This Row],[Et Kalınlığı(mm)]]*3/1000*7.85*1.4/20,1) -> 1 | G107: =_xlfn.CEILING.MATH(2*Tablo1[[#This Row],[Dış Çap(ømm)]]*3.14*Tablo1[[#This Row],[Et Kalınlığı(mm)]]*3/1000*7.85*1.4/35,1) -> 1
... A139: DN80 | B139: 90 Dirsek | C139: 88.9 | D139: 4 | E139: =Tablo1[[#This Row],[Dış Çap(ømm)]]/$C$140/$D$140*Tablo1[[#This Row],[Et Kalınlığı(mm)]] -> 1.5555556 | F139: =_xlfn.CEILING.MATH(2*Tablo1[[#This Row],[Dış Çap(ømm)]]*3.14*Tablo1[[#This Row],[Et Kalınlığı(mm)]]*3/1000*7.85*1.4/20,1) -> 4 | G139: =_xlfn.CEILING.MATH(2*Tablo1[[#This Row],[Dış Çap(ømm)]]*3.14*Tablo1[[#This Row],[Et Kalınlığı(mm)]]*3/1000*7.85*1.4/35,1) -> 3
A140: DN100 | B140: 90 Dirsek | C140: 114.3 | D140: 2 | E140: 1.33 | F140: =_xlfn.CEILING.MATH(2*Tablo1[[#This Row],[Dış Çap(ømm)]]*3.14*Tablo1[[#This Row],[Et Kalınlığı(mm)]]*3/1000*7.85*1.4/20,1) -> 3 | G140: =_xlfn.CEILING.MATH(2*Tablo1[[#This Row],[Dış Çap(ømm)]]*3.14*Tablo1[[#This Row],[Et Kalınlığı(mm)]]*3/1000*7.85*1.4/35,1) -> 2
A141: DN100 | B141: 90 Dirsek | C141: 114.3 | D141: 2.6 | E141: =(Tablo1[[#This Row],[Dış Çap(ømm)]]/$C$140)/$D$140*$E$140*Tablo1[[#This Row],[Et Kalınlığı(mm)]] -> 1.729 | F141: =_xlfn.CEILING.MATH(2*Tablo1[[#This Row],[Dış Çap(ømm)]]*3.14*Tablo1[[#This Row],[Et Kalınlığı(mm)]]*3/1000*7.85*1.4/20,1) -> 4 | G141: =_xlfn.CEILING.MATH(2*Tablo1[[#This Row],[Dış Çap(ømm)]]*3.14*Tablo1[[#This Row],[Et Kalınlığı(mm)]]*3/1000*7.85*1.4/35,1) -> 2
A142: DN100 | B142: 90 Dirsek | C142: 114.3 | D142: 3 | E142: =(Tablo1[[#This Row],[Dış Çap(ømm)]]/$C$140)/$D$140*$E$140*Tablo1[[#This Row],[Et Kalınlığı(mm)]] -> 1.995 | F142: =_xlfn.CEILING.MATH(2*Tablo1[[#This Row],[Dış Çap(ømm)]]*3.14*Tablo1[[#This Row],[Et Kalınlığı(mm)]]*3/1000*7.85*1.4/20,1) -> 4 | G142: =_xlfn.CEILING.MATH(2*Tablo1[[#This Row],[Dış Çap(ømm)]]*3.14*Tablo1[[#This Row],[Et Kalınlığı(mm)]]*3/1000*7.85*1.4/35,1) -> 3
A143: DN100 | B143: 90 Dirsek | C143: 114.3 | D143: 3.6 | E143: =(Tablo1[[#This Row],[Dış Çap(ømm)]]/$C$140)/$D$140*$E$140*Tablo1[[#This Row],[Et Kalınlığı(mm)]] -> 2.394 | F143: =_xlfn.CEILING.MATH(2*Tablo1[[#This Row],[Dış Çap(ømm)]]*3.14*Tablo1[[#This Row],[Et Kalınlığı(mm)]]*3/1000*7.85*1.4/20,1) -> 5 | G143: =_xlfn.CEILING.MATH(2*Tablo1[[#This Row],[Dış Çap(ømm)]]*3.14*Tablo1[[#This Row],[Et Kalınlığı(mm)]]*3/1000*7.85*1.4/35,1) -> 3
A144: DN100 | B144: 90 Dirsek | C144: 114.3 | D144: 4 | E144: =(Tablo1[[#This Row],[Dış Çap(ømm)]]/$C$140)/$D$140*$E$140*Tablo1[[#This Row],[Et Kalınlığı(mm)]] -> 2.66 | F144: =_xlfn.CEILING.MATH(2*Tablo1[[#This Row],[Dış Çap(ømm)]]*3.14*Tablo1[[#This Row],[Et Kalınlığı(mm)]]*3/1000*7.85*1.4/20,1) -> 5 | G144: =_xlfn.CEILING.MATH(2*Tablo1[[#This Row],[Dış Çap(ømm)]]*3.14*Tablo1[[#This Row],[Et Kalınlığı(mm)]]*3/1000*7.85*1.4/35,1) -> 3
A145: DN125 | B145: 90 Dirsek | C145: 139.7 | D145: 2 | E145: =(Tablo1[[#This Row],[Dış Çap(ømm)]]/$C$140)/$D$140*$E$140*Tablo1[[#This Row],[Et Kalınlığı(mm)]] -> 1.6255556 | F145: =_xlfn.CEILING.MATH(2*Tablo1[[#This Row],[Dış Çap(ømm)]]*3.14*Tablo1[[#This Row],[Et Kalınlığı(mm)]]*3/1000*7.85*1.4/20,1) -> 3 | G145: =_xlfn.CEILING.MATH(2*Tablo1[[#This Row],[Dış Çap(ømm)]]*3.14*Tablo1[[#This Row],[Et Kalınlığı(mm)]]*3/1000*7.85*1.4/35,1) -> 2
A146: DN125 | B146: 90 Dirsek | C146: 139.7 | D146: 2.6 | E146: =(Tablo1[[#This Row],[Dış Çap(ømm)]]/$C$140)/$D$140*$E$140*Tablo1[[#This Row],[Et Kalınlığı(mm)]] -> 2.1132222 | F146: =_xlfn.CEILING.MATH(2*Tablo1[[#This Row],[Dış Çap(ømm)]]*3.14*Tablo1[[#This Row],[Et Kalınlığı(mm)]]*3/1000*7.85*1.4/20,1) -> 4 | G146: =_xlfn.CEILING.MATH(2*Tablo1[[#This Row],[Dış Çap(ømm)]]*3.14*Tablo1[[#This Row],[Et Kalınlığı(mm)]]*3/1000*7.85*1.4/35,1) -> 3
A147: DN125 | B147: 90 Dirsek | C147: 139.7 | D147: 3 | E147: =(Tablo1[[#This Row],[Dış Çap(ømm)]]/$C$140)/$D$140*$E$140*Tablo1[[#This Row],[Et Kalınlığı(mm)]] -> 2.4383333 | F147: =_xlfn.CEILING.MATH(2*Tablo1[[#This Row],[Dış Çap(ømm)]]*3.14*Tablo1[[#This Row],[Et Kalınlığı(mm)]]*3/1000*7.85*1.4/20,1) -> 5 | G147: =_xlfn.CEILING.MATH(2*Tablo1[[#This Row],[Dış Çap(ømm)]]*3.14*Tablo1[[#This Row],[Et Kalınlığı(mm)]]*3/1000*7.85*1.4/35,1) -> 3
A148: DN125 | B148: 90 Dirsek | C148: 139.7 | D148: 4 | E148: =(Tablo1[[#This Row],[Dış Çap(ømm)]]/$C$140)/$D$140*$E$140*Tablo1[[#This Row],[Et Kalınlığı(mm)]] -> 3.2511111 | F148: =_xlfn.CEILING.MATH(2*Tablo1[[#This Row],[Dış Çap(ømm)]]*3.14*Tablo1[[#This Row],[Et Kalınlığı(mm)]]*3/1000*7.85*1.4/20,1) -> 6 | G148: =_xlfn.CEILING.MATH(2*Tablo1[[#This Row],[Dış Çap(ømm)]]*3.14*Tablo1[[#This Row],[Et Kalınlığı(mm)]]*3/1000*7.85*1.4/35,1) -> 4
A149: DN150 | B149: 90 Dirsek | C149: 168.3 | D149: 2 | E149: =(Tablo1[[#This Row],[Dış Çap(ømm)]]/$C$140)/$D$140*$E$140*Tablo1[[#This Row],[Et Kalınlığı(mm)]] -> 1.9583465 | F149: =_xlfn.CEILING.MATH(2*Tablo1[[#This Row],[Dış Çap(ømm)]]*3.14*Tablo1[[#This Row],[Et Kalınlığı(mm)]]*3/1000*7.85*1.4/20,1) -> 4 | G149: =_xlfn.CEILING.MATH(2*Tablo1[[#This Row],[Dış Çap(ømm)]]*3.14*Tablo1[[#This Row],[Et Kalınlığı(mm)]]*3/1000*7.85*1.4/35,1) -> 2
A150: DN150 | B150: 90 Dirsek | C150: 168.3 | D150: 2.6 | E150: =(Tablo1[[#This Row],[Dış Çap(ømm)]]/$C$140)/$D$140*$E$140*Tablo1[[#This Row],[Et Kalınlığı(mm)]] -> 2.5458504 | F150: =_xlfn.CEILING.MATH(2*Tablo1[[#This Row],[Dış Çap(ømm)]]*3.14*Tablo1[[#This Row],[Et Kalınlığı(mm)]]*3/1000*7.85*1.4/20,1) -> 5 | G150: =_xlfn.CEILING.MATH(2*Tablo1[[#This Row],[Dış Çap(ømm)]]*3.14*Tablo1[[#This Row],[Et Kalınlığı(mm)]]*3/1000*7.85*1.4/35,1) -> 3
A151: DN150 | B151: 90 Dirsek | C151: 168.3 | D151: 3 | E151: =(Tablo1[[#This Row],[Dış Çap(ømm)]]/$C$140)/$D$140*$E$140*Tablo1[[#This Row],[Et Kalınlığı(mm)]] -> 2.9375197 | F151: =_xlfn.CEILING.MATH(2*Tablo1[[#This Row],[Dış Çap(ømm)]]*3.14*Tablo1[[#This Row],[Et Kalınlığı(mm)]]*3/1000*7.85*1.4/20,1) -> 6 | G151: =_xlfn.CEILING.MATH(2*Tablo1[[#This Row],[Dış Çap(ømm)]]*3.14*Tablo1[[#This Row],[Et Kalınlığı(mm)]]*3/1000*7.85*1.4/35,1) -> 3
A152: DN150 | B152: 90 Dirsek | C152: 168.3 | D152: 4 | E152: =(Tablo1[[#This Row],[Dış Çap(ømm)]]/$C$140)/$D$140*$E$140*Tablo1[[#This Row],[Et Kalınlığı(mm)]] -> 3.9166929 | F152: =_xlfn.CEILING.MATH(2*Tablo1[[#This Row],[Dış Çap(ømm)]]*3.14*Tablo1[[#This Row],[Et Kalınlığı(mm)]]*3/1000*7.85*1.4/20,1) -> 7 | G152: =_xlfn.CEILING.MATH(2*Tablo1[[#This Row],[Dış Çap(ømm)]]*3.14*Tablo1[[#This Row],[Et Kalınlığı(mm)]]*3/1000*7.85*1.4/35,1) -> 4
...

Sheet Paslanmaz Fittings
A1: Çap | B1: Cins | C1: Basınç Sınıfı | D1: kg/ad | E1: Civata Çapı | F1: n | G1: Kalınlık (mm)
A2: DN15 | B2: Flanş | C2: PN6 | D2: 0.4 | E2: M10 | F2: 4 | G2: 12
A3: DN15 | B3: Flanş | C3: PN10 | D3: 0.59 | E3: M12 | F3: 4 | G3: 14
A4: DN15 | B4: Flanş | C4: PN16 | D4: 0.67 | E4: M12 | F4: 4 | G4: 14
A5: DN20 | B5: Flanş | C5: PN6 | D5: 0.59 | E5: M10 | F5: 4 | G5: 14
A6: DN20 | B6: Flanş | C6: PN10 | D6: 1.05 | E6: M12 | F6: 4 | G6: 16
A7: DN20 | B7: Flanş | C7: PN16 | D7: 0.94 | E7: M12 | F7: 4 | G7: 16
A8: DN25 | B8: Flanş | C8: PN6 | D8: 0.72 | E8: M10 | F8: 4 | G8: 14
A9: DN25 | B9: Flanş | C9: PN10 | D9: 1.25 | E9: M12 | F9: 4 | G9: 16
A10: DN25 | B10: Flanş | C10: PN16 | D10: 1.11 | E10: M12 | F10: 4 | G10: 16
A11: DN32 | B11: Flanş | C11: PN6 | D11: 1.05 | E11: M12 | F11: 4 | G11: 16
A12: DN32 | B12: Flanş | C12: PN10 | D12: 1.83 | E12: M16 | F12: 4 | G12: 18
A13: DN32 | B13: Flanş | C13: PN16 | D13: 1.7 | E13: M16 | F13: 4 | G13: 18
... A73: DN1200 | B73: Flanş | C73: PN16 | D73: 184.43 | E73: M45 | F73: 32 | G73: 98

Sheet Vanalar
A1: Çap | B1: Cins | C1: Basınç Sınıfı | D1: kg/ad | E1: Civata Çapı | F1: n | G1: Vana Kalınlığı | H1: Cıvata Boyu
A2: DN100 | B2: Demontaj | C2: PN10 | D2: 21 | E2: M16 | F2: 8 | G2: 200
A3: DN100 | B3: Demontaj | C3: PN16 | D3: 21 | E3: M16 | F3: 8 | G3: 200
A4: DN125 | B4: Demontaj | C4: PN10 | D4: 24 | E4: M16 | F4: 8 | G4: 200
A5: DN125 | B5: Demontaj | C5: PN16 | D5: 24 | E5: M16 | F5: 8 | G5: 200
A6: DN150 | B6: Demontaj | C6: PN10 | D6: 35 | E6: M20 | F6: 8 | G6: 200
A7: DN150 | B7: Demontaj | C7: PN16 | D7: 35 | E7: M20 | F7: 8 | G7: 200
A8: DN200 | B8: Demontaj | C8: PN10 | D8: 49 | E8: M20 | F8: 8 | G8: 220
A9: DN200 | B9: Demontaj | C9: PN16 | D9: 52 | E9: M20 | F9: 12 | G9: 220
A10: DN250 | B10: Demontaj | C10: PN10 | D10: 64 | E10: M20 | F10: 12 | G10: 220
A11: DN250 | B11: Demontaj | C11: PN16 | D11: 76 | E11: M24 | F11: 12 | G11: 230
A12: DN300 | B12: Demontaj | C12: PN10 | D12: 73 | E12: M20 | F12: 12 | G12: 220
A13: DN300 | B13: Demontaj | C13: PN16 | D13: 93 | E13: M24 | F13: 12 | G13: 250
... A31: DN1000 | B31: Demontaj | C31: PN16 | D31: 719 | E31: M39 | F31: 28 | G31: 340
A33: DN100 | B33: Ağırlık Kollu Çekvalf | C33: PN10 | D33: 19 | E33: M16 | F33: 8 | G33: 190 | H33: {=CONCATENATE(E33,"x",(MROUND(INDEX('Paslanmaz Fittings'!$A$2:$G$73,MATCH(1,('Paslanmaz Fittings'!$A$2:$A$73=Vanalar!A33)*('Paslanmaz Fittings'!$C$2:$C$73=Vanalar!C33),0),7)*(3.14),10)),"mm",)} -> M16x80mm
A34: DN100 | B34: Ağırlık Kollu Çekvalf | C34: PN16 | D34: 17.8 | E34: M16 | F34: 8 | G34: 190 | H34: {=CONCATENATE(E34,"x",(MROUND(INDEX('Paslanmaz Fittings'!$A$2:$G$73,MATCH(1,('Paslanmaz Fittings'!$A$2:$A$73=Vanalar!A34)*('Paslanmaz Fittings'!$C$2:$C$73=Vanalar!C34),0),7)*(3.14),10)),"mm",)} -> M16x70mm
A35: DN125 | B35: Ağırlık Kollu Çekvalf | C35: PN10 | D35: 24 | E35: M16 | F35: 8 | G35: 200 | H35: {=CONCATENATE(E35,"x",(MROUND(INDEX('Paslanmaz Fittings'!$A$2:$G$73,MATCH(1,('Paslanmaz Fittings'!$A$2:$A$73=Vanalar!A35)*('Paslanmaz Fittings'!$C$2:$C$73=Vanalar!C35),0),7)*(3.14),10)),"mm",)} -> M16x90mm
A36: DN125 | B36: Ağırlık Kollu Çekvalf | C36: PN16 | D36: 24 | E36: M16 | F36: 8 | G36: 200 | H36: {=CONCATENATE(E36,"x",(MROUND(INDEX('Paslanmaz Fittings'!$A$2:$G$73,MATCH(1,('Paslanmaz Fittings'!$A$2:$A$73=Vanalar!A36)*('Paslanmaz Fittings'!$C$2:$C$73=Vanalar!C36),0),7)*(3.14),10)),"mm",)} -> M16x70mm
A37: DN150 | B37: Ağırlık Kollu Çekvalf | C37: PN10 | D37: 30 | E37: M20 | F37: 8 | G37: 210 | H37: {=CONCATENATE(E37,"x",(MROUND(INDEX('Paslanmaz Fittings'!$A$2:$G$73,MATCH(1,('Paslanmaz Fittings'!$A$2:$A$73=Vanalar!A37)*('Paslanmaz Fittings'!$C$2:$C$73=Vanalar!C37),0),7)*(3.14),10)),"mm",)} -> M20x90mm
A38: DN150 | B38: Ağırlık Kollu Çekvalf | C38: PN16 | D38: 30 | E38: M20 | F38: 8 | G38: 210 | H38: {=CONCATENATE(E38,"x",(MROUND(INDEX('Paslanmaz Fittings'!$A$2:$G$73,MATCH(1,('Paslanmaz Fittings'!$A$2:$A$73=Vanalar!A38)*('Paslanmaz Fittings'!$C$2:$C$73=Vanalar!C38),0),7)*(3.14),10)),"mm",)} -> M20x80mm
A39: DN200 | B39: Ağırlık Kollu Çekvalf | C39: PN10 | D39: 44 | E39: M20 | F39: 8 | G39: 230 | H39: {=CONCATENATE(E39,"x",(MROUND(INDEX('Paslanmaz Fittings'!$A$2:$G$73,MATCH(1,('Paslanmaz Fittings'!$A$2:$A$73=Vanalar!A39)*('Paslanmaz Fittings'!$C$2:$C$73=Vanalar!C39),0),7)*(3.14),10)),"mm",)} -> M20x100mm
A40: DN200 | B40: Ağırlık Kollu Çekvalf | C40: PN16 | D40: 45.2 | E40: M20 | F40: 12 | G40: 230 | H40: {=CONCATENATE(E40,"x",(MROUND(INDEX('Paslanmaz Fittings'!$A$2:$G$73,MATCH(1,('Paslanmaz Fittings'!$A$2:$A$73=Vanalar!A40)*('Paslanmaz Fittings'!$C$2:$C$73=Vanalar!C40),0),7)*(3.14),10)),"mm",)} -> M20x80mm
A41: DN250 | B41: Ağırlık Kollu Çekvalf | C41: PN10 | D41: 66.5 | E41: M20 | F41: 12 | G41: 250 | H41: {=CONCATENATE(E41,"x",(MROUND(INDEX('Paslanmaz Fittings'!$A$2:$G$73,MATCH(1,('Paslanmaz Fittings'!$A$2:$A$73=Vanalar!A41)*('Paslanmaz Fittings'!$C$2:$C$73=Vanalar!C41),0),7)*(3.14),10)),"mm",)} -> M20x110mm
A42: DN250 | B42: Ağırlık Kollu Çekvalf | C42: PN16 | D42: 65 | E42: M24 | F42: 12 | G42: 250 | H42: {=CONCATENATE(E42,"x",(MROUND(INDEX('Paslanmaz Fittings'!$A$2:$G$73,MATCH(1,('Paslanmaz Fittings'!$A$2:$A$73=Vanalar!A42)*('Paslanmaz Fittings'!$C$2:$C$73=Vanalar!C42),0),7)*(3.14),10)),"mm",)} -> M24x90mm
A43: DN300 | B43: Ağırlık Kollu Çekvalf | C43: PN10 | D43: 86 | E43: M20 | F43: 12 | G43: 270 | H43: {=CONCATENATE(E43,"x",(MROUND(INDEX('Paslanmaz Fittings'!$A$2:$G$73,MATCH(1,('Paslanmaz Fittings'!$A$2:$A$73=Vanalar!A43)*('Paslanmaz Fittings'!$C$2:$C$73=Vanalar!C43),0),7)*(3.14),10)),"mm",)} -> M20x120mm
A44: DN300 | B44: Ağırlık Kollu Çekvalf | C44: PN16 | D44: 86.2 | E44: M24 | F44: 12 | G44: 270 | H44: {=CONCATENATE(E44,"x",(MROUND(INDEX('Paslanmaz Fittings'!$A$2:$G$73,MATCH(1,('Paslanmaz Fittings'!$A$2:$A$73=Vanalar!A44)*('Paslanmaz Fittings'!$C$2:$C$73=Vanalar!C44),0),7)*(3.14),10)),"mm",)} -> M24x100mm
... A62: DN1000 | B62: Ağırlık Kollu Çekvalf | C62: PN16 | D62: 1200 | E62: M39 | F62: 28 | G62: 550 | H62: {=CONCATENATE(E62,"x",(MROUND(INDEX('Paslanmaz Fittings'!$A$2:$G$73,MATCH(1,('Paslanmaz Fittings'!$A$2:$A$73=Vanalar!A62)*('Paslanmaz Fittings'!$C$2:$C$73=Vanalar!C62),0),7)*(3.14),10)),"mm",)} -> M39x280mm
A64: DN50 | B64: Çalpara Çekvalf | C64: PN16 | E64: M16 | F64: 4 | G64: 200 | H64: {=CONCATENATE(E64,"x",(MROUND(INDEX('Paslanmaz Fittings'!$A$2:$G$73,MATCH(1,('Paslanmaz Fittings'!$A$2:$A$73=Vanalar!A64)*('Paslanmaz Fittings'!$C$2:$C$73=Vanalar!C64),0),7)*(3.14),10)),"mm",)} -> M16x60mm
A65: DN65 | B65: Çalpara Çekvalf | C65: PN16 | E65: M16 | F65: 4 | G65: 240 | H65: {=CONCATENATE(E65,"x",(MROUND(INDEX('Paslanmaz Fittings'!$A$2:$G$73,MATCH(1,('Paslanmaz Fittings'!$A$2:$A$73=Vanalar!A65)*('Paslanmaz Fittings'!$C$2:$C$73=Vanalar!C65),0),7)*(3.14),10)),"mm",)} -> M16x60mm
A66: DN80 | B66: Çalpara Çekvalf | C66: PN16 | E66: M16 | F66: 8 | G66: 260 | H66: {=CONCATENATE(E66,"x",(MROUND(INDEX('Paslanmaz Fittings'!$A$2:$G$73,MATCH(1,('Paslanmaz Fittings'!$A$2:$A$73=Vanalar!A66)*('Paslanmaz Fittings'!$C$2:$C$73=Vanalar!C66),0),7)*(3.14),10)),"mm",)} -> M16x60mm
A67: DN100 | B67: Çalpara Çekvalf | C67: PN16 | E67: M16 | F67: 8 | G67: 300 | H67: {=CONCATENATE(E67,"x",(MROUND(INDEX('Paslanmaz Fittings'!$A$2:$G$73,MATCH(1,('Paslanmaz Fittings'!$A$2:$A$73=Vanalar!A67)*('Paslanmaz Fittings'!$C$2:$C$73=Vanalar!C67),0),7)*(3.14),10)),"mm",)} -> M16x70mm
A68: DN125 | B68: Çalpara Çekvalf | C68: PN16 | E68: M16 | F68: 8 | G68: 350 | H68: {=CONCATENATE(E68,"x",(MROUND(INDEX('Paslanmaz Fittings'!$A$2:$G$73,MATCH(1,('Paslanmaz Fittings'!$A$2:$A$73=Vanalar!A68)*('Paslanmaz Fittings'!$C$2:$C$73=Vanalar!C68),0),7)*(3.14),10)),"mm",)} -> M16x70mm
A69: DN150 | B69: Çalpara Çekvalf | C69: PN16 | E69: M16 | F69: 8 | G69: 400 | H69: {=CONCATENATE(E69,"x",(MROUND(INDEX('Paslanmaz Fittings'!$A$2:$G$73,MATCH(1,('Paslanmaz Fittings'!$A$2:$A$73=Vanalar!A69)*('Paslanmaz Fittings'!$C$2:$C$73=Vanalar!C69),0),7)*(3.14),10)),"mm",)} -> M16x80mm
A70: DN200 | B70: Çalpara Çekvalf | C70: PN16 | E70: M20 | F70: 12 | G70: 500 | H70: {=CONCATENATE(E70,"x",(MROUND(INDEX('Paslanmaz Fittings'!$A$2:$G$73,MATCH(1,('Paslanmaz Fittings'!$A$2:$A$73=Vanalar!A70)*('Paslanmaz Fittings'!$C$2:$C$73=Vanalar!C70),0),7)*(3.14),10)),"mm",)} -> M20x80mm
A71: DN250 | B71: Çalpara Çekvalf | C71: PN16 | E71: M24 | F71: 12 | G71: 600 | H71: {=CONCATENATE(E71,"x",(MROUND(INDEX('Paslanmaz Fittings'!$A$2:$G$73,MATCH(1,('Paslanmaz Fittings'!$A$2:$A$73=Vanalar!A71)*('Paslanmaz Fittings'!$C$2:$C$73=Vanalar!C71),0),7)*(3.14),10)),"mm",)} -> M24x90mm
A72: DN300 | B72: Çalpara Çekvalf | C72: PN16 | E72: M24 | F72: 12 | G72: 700 | H72: {=CONCATENATE(E72,"x",(MROUND(INDEX('Paslanmaz Fittings'!$A$2:$G$73,MATCH(1,('Paslanmaz Fittings'!$A$2:$A$73=Vanalar!A72)*('Paslanmaz Fittings'!$C$2:$C$73=Vanalar!C72),0),7)*(3.14),10)),"mm",)} -> M24x100mm
A74: DN40 | B74: Wafer Kelebek Vana | C74: PN6 | D74: 2 | E74: M12 | F74: 4 | G74: 33 | H74: {=CONCATENATE(E74,"x",(MROUND(INDEX('Paslanmaz Fittings'!$A$2:$G$73,MATCH(1,('Paslanmaz Fittings'!$A$2:$A$73=Vanalar!A74)*('Paslanmaz Fittings'!$C$2:$C$73=Vanalar!C74),0),7)*(3.14),10)),"mm",)} -> M12x50mm
A75: DN40 | B75: Wafer Kelebek Vana | C75: PN10 | D75: 2 | E75: M16 | F75: 4 | G75: 33 | H75: {=CONCATENATE(E75,"x",(MROUND(INDEX('Paslanmaz Fittings'!$A$2:$G$73,MATCH(1,('Paslanmaz Fittings'!$A$2:$A$73=Vanalar!A75)*('Paslanmaz Fittings'!$C$2:$C$73=Vanalar!C75),0),7)*(3.14),10)),"mm",)} -> M16x60mm
A76: DN40 | B76: Wafer Kelebek Vana | C76: PN16 | D76: 2 | E76: M16 | F76: 4 | G76: 33 | H76: {=CONCATENATE(E76,"x",(MROUND(INDEX('Paslanmaz Fittings'!$A$2:$G$73,MATCH(1,('Paslanmaz Fittings'!$A$2:$A$73=Vanalar!A76)*('Paslanmaz Fittings'!$C$2:$C$73=Vanalar!C76),0),7)*(3.14),10)),"mm",)} -> M16x60mm
A77: DN50 | B77: Wafer Kelebek Vana | C77: PN6 | D77: 2.6 | E77: M12 | F77: 4 | G77: 43 | H77: {=CONCATENATE(E77,"x",(MROUND(INDEX('Paslanmaz Fittings'!$A$2:$G$73,MATCH(1,('Paslanmaz Fittings'!$A$2:$A$73=Vanalar!A77)*('Paslanmaz Fittings'!$C$2:$C$73=Vanalar!C77),0),7)*(3.14),10)),"mm",)} -> M12x50mm
...
